Workbook

Sheet Sheet4
A1: ID | B1: Session | C1: Drug | D1: StimOrder | E1: AttrLevel | F1: DatabaseRating | G1: Gaze2 | H1: GazeDirection | I1: FaceGender | J1: Stim | K1: Rating | L1: Date
A2: 101 | B2: 1 | C2: morphine | D2: 2 | E2: 1 | F2: 5,16 | G2: A | H2: R | I2: F | J2: F067R.jpg | K2: 17.9148 | L2: 01-30-2012
A3: 101 | B3: 1 | C3: morphine | D3: 3 | E3: 3 | F3: 3,17 | G3: A | H3: L | I3: M | J3: M015L.jpg | K3: 17.11883 | L3: 01-30-2012
A4: 101 | B4: 1 | C4: morphine | D4: 4 | E4: 3 | F4: 2,38 | G4: C | H4: C | I4: F | J4: F011C.jpg | K4: 14.91031 | L4: 01-30-2012
A5: 101 | B5: 1 | C5: morphine | D5: 5 | E5: 1 | F5: 5,41 | G5: A | H5: R | I5: M | J5: M052R.jpg | K5: 21.13229 | L5: 01-30-2012
A6: 101 | B6: 1 | C6: morphine | D6: 6 | E6: 3 | F6: 3 | G6: C | H6: C | I6: F | J6: F113C.jpg | K6: 16.5583 | L6: 01-30-2012
A7: 101 | B7: 1 | C7: morphine | D7: 7 | E7: 2 | F7: 4,69 | G7: A | H7: R | I7: F | J7: F035R.jpg | K7: 19.97758 | L7: 01-30-2012
A8: 101 | B8: 1 | C8: morphine | D8: 8 | E8: 2 | F8: 4,24 | G8: C | H8: C | I8: M | J8: M087C.jpg | K8: 19.50673 | L8: 01-30-2012
A9: 101 | B9: 1 | C9: morphine | D9: 9 | E9: 1 | F9: 5,28 | G9: C | H9: C | I9: F | J9: F048C.jpg | K9: 21.97309 | L9: 01-30-2012
A10: 101 | B10: 1 | C10: morphine | D10: 10 | E10: 3 | F10: 3,32 | G10: C | H10: C | I10: F | J10: F030C.jpg | K10: 15.7287 | L10: 01-30-2012
A11: 101 | B11: 1 | C11: morphine | D11: 11 | E11: 1 | F11: 5,16 | G11: C | H11: C | I11: F | J11: F067C.jpg | K11: 17.33184 | L11: 01-30-2012
A12: 101 | B12: 1 | C12: morphine | D12: 12 | E12: 2 | F12: 4,08 | G12: C | H12: C | I12: M | J12: M029C.jpg | K12: 20.20179 | L12: 01-30-2012
A13: 101 | B13: 1 | C13: morphine | D13: 13 | E13: 3 | F13: 3,17 | G13: C | H13: C | I13: M | J13: M015C.jpg | K13: 15.45964 | L13: 01-30-2012
A14: 101 | B14: 1 | C14: morphine | D14: 14 | E14: 1 | F14: 5,28 | G14: A | H14: L | I14: F | J14: F048L.jpg | K14: 21.93946 | L14: 01-30-2012
A15: 101 | B15: 1 | C15: morphine | D15: 15 | E15: 2 | F15: 4,24 | G15: A | H15: R | I15: M | J15: M087R.jpg | K15: 19.34978 | L15: 01-30-2012
A16: 101 | B16: 1 | C16: morphine | D16: 16 | E16: 2 | F16: 4,45 | G16: C | H16: C | I16: M | J16: M049C.jpg | K16: 19.70852 | L16: 01-30-2012
A17: 101 | B17: 1 | C17: morphine | D17: 17 | E17: 1 | F17: 6,44 | G17: A | H17: R | I17: F | J17: F053R.jpg | K17: 20.70628 | L17: 01-30-2012
A18: 101 | B18: 1 | C18: morphine | D18: 18 | E18: 2 | F18: 4,45 | G18: A | H18: L | I18: M | J18: M049L.jpg | K18: 19.24888 | L18: 01-30-2012
... A29: 101 | B29: 1 | C29: morphine | D29: 29 | E29: 3 | F29: 3,01 | G29: A | H29: R | I29: M | J29: M014R.jpg | K29: 15.87444 | L29: 01-30-2012
A30: 101 | B30: 1 | C30: morphine | D30: 30 | E30: 3 | F30: 3 | G30: A | H30: R | I30: F | J30: F113R.jpg | K30: 15.52691 | L30: 01-30-2012
A31: 101 | B31: 1 | C31: morphine | D31: 31 | E31: 2 | F31: 5,02 | G31: C | H31: C | I31: F | J31: F021C.jpg | K31: 18.47534 | L31: 01-30-2012
A32: 101 | B32: 1 | C32: morphine | D32: 32 | E32: 1 | F32: 4,72 | G32: A | H32: R | I32: M | J32: M009R.jpg | K32: 18.31839 | L32: 01-30-2012
A33: 101 | B33: 1 | C33: morphine | D33: 33 | E33: 3 | F33: 3,01 | G33: C | H33: C | I33: M | J33: M014C.jpg | K33: 16.78251 | L33: 01-30-2012
A34: 101 | B34: 1 | C34: morphine | D34: 34 | E34: 3 | F34: 2,38 | G34: A | H34: L | I34: F | J34: F011L.jpg | K34: 14.76457 | L34: 01-30-2012
A35: 101 | B35: 1 | C35: morphine | D35: 35 | E35: 3 | F35: 2,53 | G35: A | H35: L | I35: M | J35: M089L.jpg | K35: 15.04484 | L35: 01-30-2012
A36: 101 | B36: 1 | C36: morphine | D36: 36 | E36: 2 | F36: 3,84 | G36: C | H36: C | I36: M | J36: M079C.jpg | K36: 16.39013 | L36: 01-30-2012
A37: 101 | B37: 1 | C37: morphine | D37: 37 | E37: 1 | F37: 4,93 | G37: A | H37: L | I37: M | J37: M022L.jpg | K37: 19.96637 | L37: 01-30-2012
A38: 101 | B38: 1 | C38: morphine | D38: 38 | E38: 2 | F38: 4,69 | G38: C | H38: C | I38: F | J38: F035C.jpg | K38: 20.40359 | L38: 01-30-2012
A39: 101 | B39: 1 | C39: morphine | D39: 39 | E39: 2 | F39: 4,98 | G39: A | H39: R | I39: F | J39: F063R.jpg | K39: 19.50673 | L39: 01-30-2012
A40: 101 | B40: 1 | C40: morphine | D40: 40 | E40: 1 | F40: 4,93 | G40: C | H40: C | I40: M | J40: M022C.jpg | K40: 20.59417 | L40: 01-30-2012
A41: 101 | B41: 1 | C41: morphine | D41: 41 | E41: 1 | F41: 5,41 | G41: C | H41: C | I41: M | J41: M052C.jpg | K41: 21.54708 | L41: 01-30-2012
A42: 101 | B42: 2 | C42: placebo | D42: 2 | E42: 3 | F42: 3,41 | G42: A | H42: L | I42: F | J42: F077L.jpg | K42: 15.42601 | L42: 41092
A43: 101 | B43: 2 | C43: placebo | D43: 3 | E43: 2 | F43: 4,48 | G43: C | H43: C | I43: M | J43: M050C.jpg | K43: 16.7713 | L43: 41092
A44: 101 | B44: 2 | C44: placebo | D44: 4 | E44: 3 | F44: 2,75 | G44: A | H44: L | I44: M | J44: M036L.jpg | K44: 14.51794 | L44: 41092
A45: 101 | B45: 2 | C45: placebo | D45: 5 | E45: 1 | F45: 4,82 | G45: A | H45: L | I45: M | J45: M023L.jpg | K45: 20.03363 | L45: 41092
A46: 101 | B46: 2 | C46: placebo | D46: 6 | E46: 3 | F46: 3,41 | G46: C | H46: C | I46: F | J46: F077C.jpg | K46: 15.61659 | L46: 41092
A47: 101 | B47: 2 | C47: placebo | D47: 7 | E47: 1 | F47: 6,28 | G47: C | H47: C | I47: F | J47: F074C.jpg | K47: 20.43722 | L47: 41092
A48: 101 | B48: 2 | C48: placebo | D48: 8 | E48: 1 | F48: 5,12 | G48: A | H48: R | I48: M | J48: M035R.jpg | K48: 18.55381 | L48: 41092
A49: 101 | B49: 2 | C49: placebo | D49: 9 | E49: 3 | F49: 3,23 | G49: A | H49: L | I49: M | J49: M034L.jpg | K49: 15.57175 | L49: 41092
A50: 101 | B50: 2 | C50: placebo | D50: 10 | E50: 3 | F50: 2,75 | G50: C | H50: C | I50: M | J50: M036C.jpg | K50: 14.76457 | L50: 41092
...

Sheet rawdataForGLM (2)
A1: ImageList | B1: ID | C1: Session | D1: Drug | E1: StimOrder | F1: AttrLevel | G1: DatabaseRating | H1: Gaze2 | I1: GazeDirection | J1: FaceGender | K1: Stim | L1: Rating | M1: Date | N1: Mean session | O1: Demeaned | P1: =MIN(O:O) -> -5.7636995 | Q1: pos demean
A2: Picture_L_1A | B2: 101 | C2: 1 | D2: A | E2: 1 | F2: 0 | G2: 0 | H2: 0 | I2: 0 | J2: 0 | K2: M093C.jpg | L2: 20.33632 | M2: 01-30-2012 | N2: =AVERAGEIFS(L:L,B:B,B2,C:C,C2) -> 18.511703 | O2: =L2-N2 -> 1.8246173
A3: Picture_L_1A | B3: 101 | C3: 1 | D3: A | E3: 2 | F3: 1 | G3: 5.16 | H3: A | I3: R | J3: F | K3: F067R.jpg | L3: 17.9148 | M3: 01-30-2012 | N3: =AVERAGEIFS(L:L,B:B,B3,C:C,C3) -> 18.511703 | O3: =L3-N3 -> -0.59690268 | Q3: =O3-P$1 -> 5.1667968
A4: Picture_L_1A | B4: 101 | C4: 1 | D4: A | E4: 3 | F4: 3 | G4: 3.17 | H4: A | I4: L | J4: M | K4: M015L.jpg | L4: 17.11883 | M4: 01-30-2012 | N4: =AVERAGEIFS(L:L,B:B,B4,C:C,C4) -> 18.511703 | O4: =L4-N4 -> -1.3928727
A5: Picture_L_1A | B5: 101 | C5: 1 | D5: A | E5: 4 | F5: 3 | G5: 2.38 | H5: C | I5: C | J5: F | K5: F011C.jpg | L5: 14.91031 | M5: 01-30-2012 | N5: =AVERAGEIFS(L:L,B:B,B5,C:C,C5) -> 18.511703 | O5: =L5-N5 -> -3.6013927 | Q5: =O5-P$1 -> 2.1623068
A6: Picture_L_1A | B6: 101 | C6: 1 | D6: A | E6: 5 | F6: 1 | G6: 5.41 | H6: A | I6: R | J6: M | K6: M052R.jpg | L6: 21.13229 | M6: 01-30-2012 | N6: =AVERAGEIFS(L:L,B:B,B6,C:C,C6) -> 18.511703 | O6: =L6-N6 -> 2.6205873
A7: Picture_L_1A | B7: 101 | C7: 1 | D7: A | E7: 6 | F7: 3 | G7: 3 | H7: C | I7: C | J7: F | K7: F113C.jpg | L7: 16.5583 | M7: 01-30-2012 | N7: =AVERAGEIFS(L:L,B:B,B7,C:C,C7) -> 18.511703 | O7: =L7-N7 -> -1.9534027 | Q7: =O7-P$1 -> 3.8102968
A8: Picture_L_1A | B8: 101 | C8: 1 | D8: A | E8: 7 | F8: 2 | G8: 4.69 | H8: A | I8: R | J8: F | K8: F035R.jpg | L8: 19.97758 | M8: 01-30-2012 | N8: =AVERAGEIFS(L:L,B:B,B8,C:C,C8) -> 18.511703 | O8: =L8-N8 -> 1.4658773 | Q8: =O8-P$1 -> 7.2295768
A9: Picture_L_1A | B9: 101 | C9: 1 | D9: A | E9: 8 | F9: 2 | G9: 4.24 | H9: C | I9: C | J9: M | K9: M087C.jpg | L9: 19.50673 | M9: 01-30-2012 | N9: =AVERAGEIFS(L:L,B:B,B9,C:C,C9) -> 18.511703 | O9: =L9-N9 -> 0.99502732
A10: Picture_L_1A | B10: 101 | C10: 1 | D10: A | E10: 9 | F10: 1 | G10: 5.28 | H10: C | I10: C | J10: F | K10: F048C.jpg | L10: 21.97309 | M10: 01-30-2012 | N10: =AVERAGEIFS(L:L,B:B,B10,C:C,C10) -> 18.511703 | O10: =L10-N10 -> 3.4613873 | Q10: =O10-P$1 -> 9.2250868
A11: Picture_L_1A | B11: 101 | C11: 1 | D11: A | E11: 10 | F11: 3 | G11: 3.32 | H11: C | I11: C | J11: F | K11: F030C.jpg | L11: 15.7287 | M11: 01-30-2012 | N11: =AVERAGEIFS(L:L,B:B,B11,C:C,C11) -> 18.511703 | O11: =L11-N11 -> -2.7830027 | Q11: =O11-P$1 -> 2.9806968
A12: Picture_L_1A | B12: 101 | C12: 1 | D12: A | E12: 11 | F12: 1 | G12: 5.16 | H12: C | I12: C | J12: F | K12: F067C.jpg | L12: 17.33184 | M12: 01-30-2012 | N12: =AVERAGEIFS(L:L,B:B,B12,C:C,C12) -> 18.511703 | O12: =L12-N12 -> -1.1798627 | Q12: =O12-P$1 -> 4.5838368
A13: Picture_L_1A | B13: 101 | C13: 1 | D13: A | E13: 12 | F13: 2 | G13: 4.08 | H13: C | I13: C | J13: M | K13: M029C.jpg | L13: 20.20179 | M13: 01-30-2012 | N13: =AVERAGEIFS(L:L,B:B,B13,C:C,C13) -> 18.511703 | O13: =L13-N13 -> 1.6900873
A14: Picture_L_1A | B14: 101 | C14: 1 | D14: A | E14: 13 | F14: 3 | G14: 3.17 | H14: C | I14: C | J14: M | K14: M015C.jpg | L14: 15.45964 | M14: 01-30-2012 | N14: =AVERAGEIFS(L:L,B:B,B14,C:C,C14) -> 18.511703 | O14: =L14-N14 -> -3.0520627
A15: Picture_L_1A | B15: 101 | C15: 1 | D15: A | E15: 14 | F15: 1 | G15: 5.28 | H15: A | I15: L | J15: F | K15: F048L.jpg | L15: 21.93946 | M15: 01-30-2012 | N15: =AVERAGEIFS(L:L,B:B,B15,C:C,C15) -> 18.511703 | O15: =L15-N15 -> 3.4277573 | Q15: =O15-P$1 -> 9.1914568
A16: Picture_L_1A | B16: 101 | C16: 1 | D16: A | E16: 15 | F16: 2 | G16: 4.24 | H16: A | I16: R | J16: M | K16: M087R.jpg | L16: 19.34978 | M16: 01-30-2012 | N16: =AVERAGEIFS(L:L,B:B,B16,C:C,C16) -> 18.511703 | O16: =L16-N16 -> 0.83807732
A17: Picture_L_1A | B17: 101 | C17: 1 | D17: A | E17: 16 | F17: 2 | G17: 4.45 | H17: C | I17: C | J17: M | K17: M049C.jpg | L17: 19.70852 | M17: 01-30-2012 | N17: =AVERAGEIFS(L:L,B:B,B17,C:C,C17) -> 18.511703 | O17: =L17-N17 -> 1.1968173
A18: Picture_L_1A | B18: 101 | C18: 1 | D18: A | E18: 17 | F18: 1 | G18: 6.44 | H18: A | I18: R | J18: F | K18: F053R.jpg | L18: 20.70628 | M18: 01-30-2012 | N18: =AVERAGEIFS(L:L,B:B,B18,C:C,C18) -> 18.511703 | O18: =L18-N18 -> 2.1945773 | Q18: =O18-P$1 -> 7.9582768
A19: Picture_L_1A | B19: 101 | C19: 1 | D19: A | E19: 18 | F19: 2 | G19: 4.45 | H19: A | I19: L | J19: M | K19: M049L.jpg | L19: 19.24888 | M19: 01-30-2012 | N19: =AVERAGEIFS(L:L,B:B,B19,C:C,C19) -> 18.511703 | O19: =L19-N19 -> 0.73717732
A20: Picture_L_1A | B20: 101 | C20: 1 | D20: A | E20: 19 | F20: 2 | G20: 4.8 | H20: C | I20: C | J20: F | K20: F056C.jpg | L20: 19.42825 | M20: 01-30-2012 | N20: =AVERAGEIFS(L:L,B:B,B20,C:C,C20) -> 18.511703 | O20: =L20-N20 -> 0.91654732 | Q20: =O20-P$1 -> 6.6802468
A21: Picture_L_1A | B21: 101 | C21: 1 | D21: A | E21: 20 | F21: 3 | G21: 3.32 | H21: A | I21: L | J21: F | K21: F030L.jpg | L21: 15.36996 | M21: 01-30-2012 | N21: =AVERAGEIFS(L:L,B:B,B21,C:C,C21) -> 18.511703 | O21: =L21-N21 -> -3.1417427 | Q21: =O21-P$1 -> 2.6219568
A22: Picture_L_1A | B22: 101 | C22: 1 | D22: A | E22: 21 | F22: 2 | G22: 5.02 | H22: A | I22: L | J22: F | K22: F021L.jpg | L22: 19.1704 | M22: 01-30-2012 | N22: =AVERAGEIFS(L:L,B:B,B22,C:C,C22) -> 18.511703 | O22: =L22-N22 -> 0.65869732 | Q22: =O22-P$1 -> 6.4223968
A23: Picture_L_1A | B23: 101 | C23: 1 | D23: A | E23: 22 | F23: 2 | G23: 4.8 | H23: A | I23: L | J23: F | K23: F056L.jpg | L23: 19.02466 | M23: 01-30-2012 | N23: =AVERAGEIFS(L:L,B:B,B23,C:C,C23) -> 18.511703 | O23: =L23-N23 -> 0.51295732 | Q23: =O23-P$1 -> 6.2766568
A24: Picture_L_1A | B24: 101 | C24: 1 | D24: A | E24: 23 | F24: 2 | G24: 3.84 | H24: A | I24: R | J24: M | K24: M079R.jpg | L24: 17.98206 | M24: 01-30-2012 | N24: =AVERAGEIFS(L:L,B:B,B24,C:C,C24) -> 18.511703 | O24: =L24-N24 -> -0.52964268
A25: Picture_L_1A | B25: 101 | C25: 1 | D25: A | E25: 24 | F25: 3 | G25: 2.53 | H25: C | I25: C | J25: M | K25: M089C.jpg | L25: 17.32063 | M25: 01-30-2012 | N25: =AVERAGEIFS(L:L,B:B,B25,C:C,C25) -> 18.511703 | O25: =L25-N25 -> -1.1910727
A26: Picture_L_1A | B26: 101 | C26: 1 | D26: A | E26: 25 | F26: 2 | G26: 4.08 | H26: A | I26: L | J26: M | K26: M029L.jpg | L26: 20.84081 | M26: 01-30-2012 | N26: =AVERAGEIFS(L:L,B:B,B26,C:C,C26) -> 18.511703 | O26: =L26-N26 -> 2.3291073
A27: Picture_L_1A | B27: 101 | C27: 1 | D27: A | E27: 26 | F27: 2 | G27: 4.98 | H27: C | I27: C | J27: F | K27: F063C.jpg | L27: 18.16143 | M27: 01-30-2012 | N27: =AVERAGEIFS(L:L,B:B,B27,C:C,C27) -> 18.511703 | O27: =L27-N27 -> -0.35027268 | Q27: =O27-P$1 -> 5.4134268
A28: Picture_L_1A | B28: 101 | C28: 1 | D28: A | E28: 27 | F28: 1 | G28: 4.72 | H28: C | I28: C | J28: M | K28: M009C.jpg | L28: 18.29596 | M28: 01-30-2012 | N28: =AVERAGEIFS(L:L,B:B,B28,C:C,C28) -> 18.511703 | O28: =L28-N28 -> -0.21574268
A29: Picture_L_1A | B29: 101 | C29: 1 | D29: A | E29: 28 | F29: 1 | G29: 6.44 | H29: C | I29: C | J29: F | K29: F053C.jpg | L29: 21.08744 | M29: 01-30-2012 | N29: =AVERAGEIFS(L:L,B:B,B29,C:C,C29) -> 18.511703 | O29: =L29-N29 -> 2.5757373 | Q29: =O29-P$1 -> 8.3394368
A30: Picture_L_1A | B30: 101 | C30: 1 | D30: A | E30: 29 | F30: 3 | G30: 3.01 | H30: A | I30: R | J30: M | K30: M014R.jpg | L30: 15.87444 | M30: 01-30-2012 | N30: =AVERAGEIFS(L:L,B:B,B30,C:C,C30) -> 18.511703 | O30: =L30-N30 -> -2.6372627
A31: Picture_L_1A | B31: 101 | C31: 1 | D31: A | E31: 30 | F31: 3 | G31: 3 | H31: A | I31: R | J31: F | K31: F113R.jpg | L31: 15.52691 | M31: 01-30-2012 | N31: =AVERAGEIFS(L:L,B:B,B31,C:C,C31) -> 18.511703 | O31: =L31-N31 -> -2.9847927 | Q31: =O31-P$1 -> 2.7789068
A32: Picture_L_1A | B32: 101 | C32: 1 | D32: A | E32: 31 | F32: 2 | G32: 5.02 | H32: C | I32: C | J32: F | K32: F021C.jpg | L32: 18.47534 | M32: 01-30-2012 | N32: =AVERAGEIFS(L:L,B:B,B32,C:C,C32) -> 18.511703 | O32: =L32-N32 -> -0.036362683 | Q32: =O32-P$1 -> 5.7273368
A33: Picture_L_1A | B33: 101 | C33: 1 | D33: A | E33: 32 | F33: 1 | G33: 4.72 | H33: A | I33: R | J33: M | K33: M009R.jpg | L33: 18.31839 | M33: 01-30-2012 | N33: =AVERAGEIFS(L:L,B:B,B33,C:C,C33) -> 18.511703 | O33: =L33-N33 -> -0.19331268
A34: Picture_L_1A | B34: 101 | C34: 1 | D34: A | E34: 33 | F34: 3 | G34: 3.01 | H34: C | I34: C | J34: M | K34: M014C.jpg | L34: 16.78251 | M34: 01-30-2012 | N34: =AVERAGEIFS(L:L,B:B,B34,C:C,C34) -> 18.511703 | O34: =L34-N34 -> -1.7291927
A35: Picture_L_1A | B35: 101 | C35: 1 | D35: A | E35: 34 | F35: 3 | G35: 2.38 | H35: A | I35: L | J35: F | K35: F011L.jpg | L35: 14.76457 | M35: 01-30-2012 | N35: =AVERAGEIFS(L:L,B:B,B35,C:C,C35) -> 18.511703 | O35: =L35-N35 -> -3.7471327 | Q35: =O35-P$1 -> 2.0165668
A36: Picture_L_1A | B36: 101 | C36: 1 | D36: A | E36: 35 | F36: 3 | G36: 2.53 | H36: A | I36: L | J36: M | K36: M089L.jpg | L36: 15.04484 | M36: 01-30-2012 | N36: =AVERAGEIFS(L:L,B:B,B36,C:C,C36) -> 18.511703 | O36: =L36-N36 -> -3.4668627
A37: Picture_L_1A | B37: 101 | C37: 1 | D37: A | E37: 36 | F37: 2 | G37: 3.84 | H37: C | I37: C | J37: M | K37: M079C.jpg | L37: 16.39013 | M37: 01-30-2012 | N37: =AVERAGEIFS(L:L,B:B,B37,C:C,C37) -> 18.511703 | O37: =L37-N37 -> -2.1215727
A38: Picture_L_1A | B38: 101 | C38: 1 | D38: A | E38: 37 | F38: 1 | G38: 4.93 | H38: A | I38: L | J38: M | K38: M022L.jpg | L38: 19.96637 | M38: 01-30-2012 | N38: =AVERAGEIFS(L:L,B:B,B38,C:C,C38) -> 18.511703 | O38: =L38-N38 -> 1.4546673
A39: Picture_L_1A | B39: 101 | C39: 1 | D39: A | E39: 38 | F39: 2 | G39: 4.69 | H39: C | I39: C | J39: F | K39: F035C.jpg | L39: 20.40359 | M39: 01-30-2012 | N39: =AVERAGEIFS(L:L,B:B,B39,C:C,C39) -> 18.511703 | O39: =L39-N39 -> 1.8918873 | Q39: =O39-P$1 -> 7.6555868
A40: Picture_L_1A | B40: 101 | C40: 1 | D40: A | E40: 39 | F40: 2 | G40: 4.98 | H40: A | I40: R | J40: F | K40: F063R.jpg | L40: 19.50673 | M40: 01-30-2012 | N40: =AVERAGEIFS(L:L,B:B,B40,C:C,C40) -> 18.511703 | O40: =L40-N40 -> 0.99502732 | Q40: =O40-P$1 -> 6.7587268
...

Sheet rawdataForGLM graphpad
A1: ImageList | B1: ID | C1: Session | D1: Drug | E1: StimOrder | F1: AttrLevel | G1: DatabaseRating | H1: Gaze2 | I1: GazeDirection | J1: FaceGender | K1: Stim | L1: Rating | M1: Date | N1: Rating-12.95 | O1: =B1 -> ID | P1: =C1 -> Session | Q1: =F1 -> AttrLevel | R1: =E1 -> StimOrder | S1: Drug | T1: =L1 -> Rating | U1: =H1 -> Gaze2 | V1: ImageList2 | W1: Sex2 | Y1: F only
A2: Picture_L_1A | B2: 101 | C2: 1 | D2: A | E2: 1 | F2: 0 | H2: 0 | I2: 0 | J2: 0 | K2: M093C.jpg | L2: 20.33632 | M2: 01-30-2012 | N2: =L2-12.95 -> 7.38632 | O2: =B2 -> 101 | P2: =C2 -> 1 | Q2: =F2 -> 0 | R2: =E2-1 -> 0 | S2: =IF(D2=D$2,1,IF(D2=D$43,2,IF(D2=D$84,3))) -> 1 | T2: =L2 -> 20.33632 | U2: =IF(H2=H$5,1,2) -> 2 | V2: =MID(A2,11,1) -> 1 | W2: =IF(J2=J$3,1,2) -> 2
A3: Picture_L_1A | B3: 101 | C3: 1 | D3: A | E3: 2 | F3: 1 | G3: 5.16 | H3: A | I3: R | J3: F | K3: F067R.jpg | L3: 17.9148 | M3: 01-30-2012 | N3: =L3-12.95 -> 4.9648 | O3: =B3 -> 101 | P3: =C3 -> 1 | Q3: =F3 -> 1 | R3: =E3-1 -> 1 | S3: =IF(D3=D$2,1,IF(D3=D$43,2,IF(D3=D$84,3))) -> 1 | T3: =L3 -> 17.9148 | U3: =IF(H3=H$5,1,2) -> 2 | V3: =MID(A3,11,1) -> 1 | W3: =IF(J3=J$3,1,2) -> 1 | Y3: 0.2922 | Z3: =SQRT(Y3) -> 0.54055527
A4: Picture_L_1A | B4: 101 | C4: 1 | D4: A | E4: 3 | F4: 3 | G4: 3.17 | H4: A | I4: L | J4: M | K4: M015L.jpg | L4: 17.11883 | M4: 01-30-2012 | N4: =L4-12.95 -> 4.16883 | O4: =B4 -> 101 | P4: =C4 -> 1 | Q4: =F4 -> 3 | R4: =E4-1 -> 2 | S4: =IF(D4=D$2,1,IF(D4=D$43,2,IF(D4=D$84,3))) -> 1 | T4: =L4 -> 17.11883 | U4: =IF(H4=H$5,1,2) -> 2 | V4: =MID(A4,11,1) -> 1 | W4: =IF(J4=J$3,1,2) -> 2
A5: Picture_L_1A | B5: 101 | C5: 1 | D5: A | E5: 4 | F5: 3 | G5: 2.38 | H5: C | I5: C | J5: F | K5: F011C.jpg | L5: 14.91031 | M5: 01-30-2012 | N5: =L5-12.95 -> 1.96031 | O5: =B5 -> 101 | P5: =C5 -> 1 | Q5: =F5 -> 3 | R5: =E5-1 -> 3 | S5: =IF(D5=D$2,1,IF(D5=D$43,2,IF(D5=D$84,3))) -> 1 | T5: =L5 -> 14.91031 | U5: =IF(H5=H$5,1,2) -> 1 | V5: =MID(A5,11,1) -> 1 | W5: =IF(J5=J$3,1,2) -> 1 | Y5: 0.3101 | Z5: =SQRT(Y5) -> 0.55686623
A6: Picture_L_1A | B6: 101 | C6: 1 | D6: A | E6: 5 | F6: 1 | G6: 5.41 | H6: A | I6: R | J6: M | K6: M052R.jpg | L6: 21.13229 | M6: 01-30-2012 | N6: =L6-12.95 -> 8.18229 | O6: =B6 -> 101 | P6: =C6 -> 1 | Q6: =F6 -> 1 | R6: =E6-1 -> 4 | S6: =IF(D6=D$2,1,IF(D6=D$43,2,IF(D6=D$84,3))) -> 1 | T6: =L6 -> 21.13229 | U6: =IF(H6=H$5,1,2) -> 2 | V6: =MID(A6,11,1) -> 1 | W6: =IF(J6=J$3,1,2) -> 2
A7: Picture_L_1A | B7: 101 | C7: 1 | D7: A | E7: 6 | F7: 3 | G7: 3 | H7: C | I7: C | J7: F | K7: F113C.jpg | L7: 16.5583 | M7: 01-30-2012 | N7: =L7-12.95 -> 3.6083 | O7: =B7 -> 101 | P7: =C7 -> 1 | Q7: =F7 -> 3 | R7: =E7-1 -> 5 | S7: =IF(D7=D$2,1,IF(D7=D$43,2,IF(D7=D$84,3))) -> 1 | T7: =L7 -> 16.5583 | U7: =IF(H7=H$5,1,2) -> 1 | V7: =MID(A7,11,1) -> 1 | W7: =IF(J7=J$3,1,2) -> 1 | Y7: 0.2276 | Z7: =SQRT(Y7) -> 0.47707442
A8: Picture_L_1A | B8: 101 | C8: 1 | D8: A | E8: 7 | F8: 2 | G8: 4.69 | H8: A | I8: R | J8: F | K8: F035R.jpg | L8: 19.97758 | M8: 01-30-2012 | N8: =L8-12.95 -> 7.02758 | O8: =B8 -> 101 | P8: =C8 -> 1 | Q8: =F8 -> 2 | R8: =E8-1 -> 6 | S8: =IF(D8=D$2,1,IF(D8=D$43,2,IF(D8=D$84,3))) -> 1 | T8: =L8 -> 19.97758 | U8: =IF(H8=H$5,1,2) -> 2 | V8: =MID(A8,11,1) -> 1 | W8: =IF(J8=J$3,1,2) -> 1
A9: Picture_L_1A | B9: 101 | C9: 1 | D9: A | E9: 8 | F9: 2 | G9: 4.24 | H9: C | I9: C | J9: M | K9: M087C.jpg | L9: 19.50673 | M9: 01-30-2012 | N9: =L9-12.95 -> 6.55673 | O9: =B9 -> 101 | P9: =C9 -> 1 | Q9: =F9 -> 2 | R9: =E9-1 -> 7 | S9: =IF(D9=D$2,1,IF(D9=D$43,2,IF(D9=D$84,3))) -> 1 | T9: =L9 -> 19.50673 | U9: =IF(H9=H$5,1,2) -> 1 | V9: =MID(A9,11,1) -> 1 | W9: =IF(J9=J$3,1,2) -> 2
A10: Picture_L_1A | B10: 101 | C10: 1 | D10: A | E10: 9 | F10: 1 | G10: 5.28 | H10: C | I10: C | J10: F | K10: F048C.jpg | L10: 21.97309 | M10: 01-30-2012 | N10: =L10-12.95 -> 9.02309 | O10: =B10 -> 101 | P10: =C10 -> 1 | Q10: =F10 -> 1 | R10: =E10-1 -> 8 | S10: =IF(D10=D$2,1,IF(D10=D$43,2,IF(D10=D$84,3))) -> 1 | T10: =L10 -> 21.97309 | U10: =IF(H10=H$5,1,2) -> 1 | V10: =MID(A10,11,1) -> 1 | W10: =IF(J10=J$3,1,2) -> 1 | Y10: 0.2563 | Z10: =SQRT(Y10) -> 0.5062608
A11: Picture_L_1A | B11: 101 | C11: 1 | D11: A | E11: 10 | F11: 3 | G11: 3.32 | H11: C | I11: C | J11: F | K11: F030C.jpg | L11: 15.7287 | M11: 01-30-2012 | N11: =L11-12.95 -> 2.7787 | O11: =B11 -> 101 | P11: =C11 -> 1 | Q11: =F11 -> 3 | R11: =E11-1 -> 9 | S11: =IF(D11=D$2,1,IF(D11=D$43,2,IF(D11=D$84,3))) -> 1 | T11: =L11 -> 15.7287 | U11: =IF(H11=H$5,1,2) -> 1 | V11: =MID(A11,11,1) -> 1 | W11: =IF(J11=J$3,1,2) -> 1 | Y11: 0.2543 | Z11: =SQRT(Y11) -> 0.50428167
A12: Picture_L_1A | B12: 101 | C12: 1 | D12: A | E12: 11 | F12: 1 | G12: 5.16 | H12: C | I12: C | J12: F | K12: F067C.jpg | L12: 17.33184 | M12: 01-30-2012 | N12: =L12-12.95 -> 4.38184 | O12: =B12 -> 101 | P12: =C12 -> 1 | Q12: =F12 -> 1 | R12: =E12-1 -> 10 | S12: =IF(D12=D$2,1,IF(D12=D$43,2,IF(D12=D$84,3))) -> 1 | T12: =L12 -> 17.33184 | U12: =IF(H12=H$5,1,2) -> 1 | V12: =MID(A12,11,1) -> 1 | W12: =IF(J12=J$3,1,2) -> 1 | Y12: 0.2153 | Z12: =SQRT(Y12) -> 0.46400431
A13: Picture_L_1A | B13: 101 | C13: 1 | D13: A | E13: 12 | F13: 2 | G13: 4.08 | H13: C | I13: C | J13: M | K13: M029C.jpg | L13: 20.20179 | M13: 01-30-2012 | N13: =L13-12.95 -> 7.25179 | O13: =B13 -> 101 | P13: =C13 -> 1 | Q13: =F13 -> 2 | R13: =E13-1 -> 11 | S13: =IF(D13=D$2,1,IF(D13=D$43,2,IF(D13=D$84,3))) -> 1 | T13: =L13 -> 20.20179 | U13: =IF(H13=H$5,1,2) -> 1 | V13: =MID(A13,11,1) -> 1 | W13: =IF(J13=J$3,1,2) -> 2
A14: Picture_L_1A | B14: 101 | C14: 1 | D14: A | E14: 13 | F14: 3 | G14: 3.17 | H14: C | I14: C | J14: M | K14: M015C.jpg | L14: 15.45964 | M14: 01-30-2012 | N14: =L14-12.95 -> 2.50964 | O14: =B14 -> 101 | P14: =C14 -> 1 | Q14: =F14 -> 3 | R14: =E14-1 -> 12 | S14: =IF(D14=D$2,1,IF(D14=D$43,2,IF(D14=D$84,3))) -> 1 | T14: =L14 -> 15.45964 | U14: =IF(H14=H$5,1,2) -> 1 | V14: =MID(A14,11,1) -> 1 | W14: =IF(J14=J$3,1,2) -> 2
A15: Picture_L_1A | B15: 101 | C15: 1 | D15: A | E15: 14 | F15: 1 | G15: 5.28 | H15: A | I15: L | J15: F | K15: F048L.jpg | L15: 21.93946 | M15: 01-30-2012 | N15: =L15-12.95 -> 8.98946 | O15: =B15 -> 101 | P15: =C15 -> 1 | Q15: =F15 -> 1 | R15: =E15-1 -> 13 | S15: =IF(D15=D$2,1,IF(D15=D$43,2,IF(D15=D$84,3))) -> 1 | T15: =L15 -> 21.93946 | U15: =IF(H15=H$5,1,2) -> 2 | V15: =MID(A15,11,1) -> 1 | W15: =IF(J15=J$3,1,2) -> 1
A16: Picture_L_1A | B16: 101 | C16: 1 | D16: A | E16: 15 | F16: 2 | G16: 4.24 | H16: A | I16: R | J16: M | K16: M087R.jpg | L16: 19.34978 | M16: 01-30-2012 | N16: =L16-12.95 -> 6.39978 | O16: =B16 -> 101 | P16: =C16 -> 1 | Q16: =F16 -> 2 | R16: =E16-1 -> 14 | S16: =IF(D16=D$2,1,IF(D16=D$43,2,IF(D16=D$84,3))) -> 1 | T16: =L16 -> 19.34978 | U16: =IF(H16=H$5,1,2) -> 2 | V16: =MID(A16,11,1) -> 1 | W16: =IF(J16=J$3,1,2) -> 2
A17: Picture_L_1A | B17: 101 | C17: 1 | D17: A | E17: 16 | F17: 2 | G17: 4.45 | H17: C | I17: C | J17: M | K17: M049C.jpg | L17: 19.70852 | M17: 01-30-2012 | N17: =L17-12.95 -> 6.75852 | O17: =B17 -> 101 | P17: =C17 -> 1 | Q17: =F17 -> 2 | R17: =E17-1 -> 15 | S17: =IF(D17=D$2,1,IF(D17=D$43,2,IF(D17=D$84,3))) -> 1 | T17: =L17 -> 19.70852 | U17: =IF(H17=H$5,1,2) -> 1 | V17: =MID(A17,11,1) -> 1 | W17: =IF(J17=J$3,1,2) -> 2
A18: Picture_L_1A | B18: 101 | C18: 1 | D18: A | E18: 17 | F18: 1 | G18: 6.44 | H18: A | I18: R | J18: F | K18: F053R.jpg | L18: 20.70628 | M18: 01-30-2012 | N18: =L18-12.95 -> 7.75628 | O18: =B18 -> 101 | P18: =C18 -> 1 | Q18: =F18 -> 1 | R18: =E18-1 -> 16 | S18: =IF(D18=D$2,1,IF(D18=D$43,2,IF(D18=D$84,3))) -> 1 | T18: =L18 -> 20.70628 | U18: =IF(H18=H$5,1,2) -> 2 | V18: =MID(A18,11,1) -> 1 | W18: =IF(J18=J$3,1,2) -> 1
A19: Picture_L_1A | B19: 101 | C19: 1 | D19: A | E19: 18 | F19: 2 | G19: 4.45 | H19: A | I19: L | J19: M | K19: M049L.jpg | L19: 19.24888 | M19: 01-30-2012 | N19: =L19-12.95 -> 6.29888 | O19: =B19 -> 101 | P19: =C19 -> 1 | Q19: =F19 -> 2 | R19: =E19-1 -> 17 | S19: =IF(D19=D$2,1,IF(D19=D$43,2,IF(D19=D$84,3))) -> 1 | T19: =L19 -> 19.24888 | U19: =IF(H19=H$5,1,2) -> 2 | V19: =MID(A19,11,1) -> 1 | W19: =IF(J19=J$3,1,2) -> 2
A20: Picture_L_1A | B20: 101 | C20: 1 | D20: A | E20: 19 | F20: 2 | G20: 4.8 | H20: C | I20: C | J20: F | K20: F056C.jpg | L20: 19.42825 | M20: 01-30-2012 | N20: =L20-12.95 -> 6.47825 | O20: =B20 -> 101 | P20: =C20 -> 1 | Q20: =F20 -> 2 | R20: =E20-1 -> 18 | S20: =IF(D20=D$2,1,IF(D20=D$43,2,IF(D20=D$84,3))) -> 1 | T20: =L20 -> 19.42825 | U20: =IF(H20=H$5,1,2) -> 1 | V20: =MID(A20,11,1) -> 1 | W20: =IF(J20=J$3,1,2) -> 1
A21: Picture_L_1A | B21: 101 | C21: 1 | D21: A | E21: 20 | F21: 3 | G21: 3.32 | H21: A | I21: L | J21: F | K21: F030L.jpg | L21: 15.36996 | M21: 01-30-2012 | N21: =L21-12.95 -> 2.41996 | O21: =B21 -> 101 | P21: =C21 -> 1 | Q21: =F21 -> 3 | R21: =E21-1 -> 19 | S21: =IF(D21=D$2,1,IF(D21=D$43,2,IF(D21=D$84,3))) -> 1 | T21: =L21 -> 15.36996 | U21: =IF(H21=H$5,1,2) -> 2 | V21: =MID(A21,11,1) -> 1 | W21: =IF(J21=J$3,1,2) -> 1
A22: Picture_L_1A | B22: 101 | C22: 1 | D22: A | E22: 21 | F22: 2 | G22: 5.02 | H22: A | I22: L | J22: F | K22: F021L.jpg | L22: 19.1704 | M22: 01-30-2012 | N22: =L22-12.95 -> 6.2204 | O22: =B22 -> 101 | P22: =C22 -> 1 | Q22: =F22 -> 2 | R22: =E22-1 -> 20 | S22: =IF(D22=D$2,1,IF(D22=D$43,2,IF(D22=D$84,3))) -> 1 | T22: =L22 -> 19.1704 | U22: =IF(H22=H$5,1,2) -> 2 | V22: =MID(A22,11,1) -> 1 | W22: =IF(J22=J$3,1,2) -> 1
A23: Picture_L_1A | B23: 101 | C23: 1 | D23: A | E23: 22 | F23: 2 | G23: 4.8 | H23: A | I23: L | J23: F | K23: F056L.jpg | L23: 19.02466 | M23: 01-30-2012 | N23: =L23-12.95 -> 6.07466 | O23: =B23 -> 101 | P23: =C23 -> 1 | Q23: =F23 -> 2 | R23: =E23-1 -> 21 | S23: =IF(D23=D$2,1,IF(D23=D$43,2,IF(D23=D$84,3))) -> 1 | T23: =L23 -> 19.02466 | U23: =IF(H23=H$5,1,2) -> 2 | V23: =MID(A23,11,1) -> 1 | W23: =IF(J23=J$3,1,2) -> 1
A24: Picture_L_1A | B24: 101 | C24: 1 | D24: A | E24: 23 | F24: 2 | G24: 3.84 | H24: A | I24: R | J24: M | K24: M079R.jpg | L24: 17.98206 | M24: 01-30-2012 | N24: =L24-12.95 -> 5.03206 | O24: =B24 -> 101 | P24: =C24 -> 1 | Q24: =F24 -> 2 | R24: =E24-1 -> 22 | S24: =IF(D24=D$2,1,IF(D24=D$43,2,IF(D24=D$84,3))) -> 1 | T24: =L24 -> 17.98206 | U24: =IF(H24=H$5,1,2) -> 2 | V24: =MID(A24,11,1) -> 1 | W24: =IF(J24=J$3,1,2) -> 2
... A42: Picture_L_1A | B42: 101 | C42: 1 | D42: A | E42: 41 | F42: 1 | G42: 5.41 | H42: C | I42: C | J42: M | K42: M052C.jpg | L42: 21.54708 | M42: 01-30-2012 | N42: =L42-12.95 -> 8.59708 | O42: =B42 -> 101 | P42: =C42 -> 1 | Q42: =F42 -> 1 | R42: =E42-1 -> 40 | S42: =IF(D42=D$2,1,IF(D42=D$43,2,IF(D42=D$84,3))) -> 1 | T42: =L42 -> 21.54708 | U42: =IF(H42=H$5,1,2) -> 1 | V42: =MID(A42,11,1) -> 1 | W42: =IF(J42=J$3,1,2) -> 2
A43: Picture_L_6B | B43: 102 | C43: 1 | D43: A | E43: 1 | F43: 0 | H43: 0 | I43: 0 | J43: 0 | K43: F098L.jpg | L43: 13.9574 | M43: 01-30-2012 | N43: =L43-12.95 -> 1.0074 | O43: =B43 -> 102 | P43: =C43 -> 1 | Q43: =F43 -> 0 | R43: =E43-1 -> 0 | S43: =IF(D43=D$2,1,IF(D43=D$43,2,IF(D43=D$84,3))) -> 1 | T43: =L43 -> 13.9574 | U43: =IF(H43=H$5,1,2) -> 2 | V43: =MID(A43,11,1) -> 6 | W43: =IF(J43=J$3,1,2) -> 2
A44: Picture_L_6B | B44: 102 | C44: 1 | D44: A | E44: 2 | F44: 2 | G44: 4.37 | H44: A | I44: L | J44: M | K44: M011L.jpg | L44: 14.26009 | M44: 01-30-2012 | N44: =L44-12.95 -> 1.31009 | O44: =B44 -> 102 | P44: =C44 -> 1 | Q44: =F44 -> 2 | R44: =E44-1 -> 1 | S44: =IF(D44=D$2,1,IF(D44=D$43,2,IF(D44=D$84,3))) -> 1 | T44: =L44 -> 14.26009 | U44: =IF(H44=H$5,1,2) -> 2 | V44: =MID(A44,11,1) -> 6 | W44: =IF(J44=J$3,1,2) -> 2
A45: Picture_L_6B | B45: 102 | C45: 1 | D45: A | E45: 3 | F45: 1 | G45: 4.66 | H45: C | I45: C | J45: M | K45: M026C.jpg | L45: 14.39462 | M45: 01-30-2012 | N45: =L45-12.95 -> 1.44462 | O45: =B45 -> 102 | P45: =C45 -> 1 | Q45: =F45 -> 1 | R45: =E45-1 -> 2 | S45: =IF(D45=D$2,1,IF(D45=D$43,2,IF(D45=D$84,3))) -> 1 | T45: =L45 -> 14.39462 | U45: =IF(H45=H$5,1,2) -> 1 | V45: =MID(A45,11,1) -> 6 | W45: =IF(J45=J$3,1,2) -> 2
A46: Picture_L_6B | B46: 102 | C46: 1 | D46: A | E46: 4 | F46: 2 | G46: 4.94 | H46: A | I46: R | J46: F | K46: F049R.jpg | L46: 15.03363 | M46: 01-30-2012 | N46: =L46-12.95 -> 2.08363 | O46: =B46 -> 102 | P46: =C46 -> 1 | Q46: =F46 -> 2 | R46: =E46-1 -> 3 | S46: =IF(D46=D$2,1,IF(D46=D$43,2,IF(D46=D$84,3))) -> 1 | T46: =L46 -> 15.03363 | U46: =IF(H46=H$5,1,2) -> 2 | V46: =MID(A46,11,1) -> 6 | W46: =IF(J46=J$3,1,2) -> 1
A47: Picture_L_6B | B47: 102 | C47: 1 | D47: A | E47: 5 | F47: 2 | G47: 4.04 | H47: A | I47: L | J47: M | K47: M047L.jpg | L47: 13.25112 | M47: 01-30-2012 | N47: =L47-12.95 -> 0.30112 | O47: =B47 -> 102 | P47: =C47 -> 1 | Q47: =F47 -> 2 | R47: =E47-1 -> 4 | S47: =IF(D47=D$2,1,IF(D47=D$43,2,IF(D47=D$84,3))) -> 1 | T47: =L47 -> 13.25112 | U47: =IF(H47=H$5,1,2) -> 2 | V47: =MID(A47,11,1) -> 6 | W47: =IF(J47=J$3,1,2) -> 2
A48: Picture_L_6B | B48: 102 | C48: 1 | D48: A | E48: 6 | F48: 2 | G48: 4.94 | H48: C | I48: C | J48: F | K48: F049C.jpg | L48: 14.95516 | M48: 01-30-2012 | N48: =L48-12.95 -> 2.00516 | O48: =B48 -> 102 | P48: =C48 -> 1 | Q48: =F48 -> 2 | R48: =E48-1 -> 5 | S48: =IF(D48=D$2,1,IF(D48=D$43,2,IF(D48=D$84,3))) -> 1 | T48: =L48 -> 14.95516 | U48: =IF(H48=H$5,1,2) -> 1 | V48: =MID(A48,11,1) -> 6 | W48: =IF(J48=J$3,1,2) -> 1
A49: Picture_L_6B | B49: 102 | C49: 1 | D49: A | E49: 7 | F49: 2 | G49: 4.68 | H49: C | I49: C | J49: F | K49: F013C.jpg | L49: 14.50673 | M49: 01-30-2012 | N49: =L49-12.95 -> 1.55673 | O49: =B49 -> 102 | P49: =C49 -> 1 | Q49: =F49 -> 2 | R49: =E49-1 -> 6 | S49: =IF(D49=D$2,1,IF(D49=D$43,2,IF(D49=D$84,3))) -> 1 | T49: =L49 -> 14.50673 | U49: =IF(H49=H$5,1,2) -> 1 | V49: =MID(A49,11,1) -> 6 | W49: =IF(J49=J$3,1,2) -> 1
A50: Picture_L_6B | B50: 102 | C50: 1 | D50: A | E50: 8 | F50: 3 | G50: 3.25 | H50: C | I50: C | J50: F | K50: F052C.jpg | L50: 13.20628 | M50: 01-30-2012 | N50: =L50-12.95 -> 0.25628 | O50: =B50 -> 102 | P50: =C50 -> 1 | Q50: =F50 -> 3 | R50: =E50-1 -> 7 | S50: =IF(D50=D$2,1,IF(D50=D$43,2,IF(D50=D$84,3))) -> 1 | T50: =L50 -> 13.20628 | U50: =IF(H50=H$5,1,2) -> 1 | V50: =MID(A50,11,1) -> 6 | W50: =IF(J50=J$3,1,2) -> 1
A51: Picture_L_6B | B51: 102 | C51: 1 | D51: A | E51: 9 | F51: 1 | G51: 5.35 | H51: A | I51: R | J51: M | K51: M055R.jpg | L51: 16.23318 | M51: 01-30-2012 | N51: =L51-12.95 -> 3.28318 | O51: =B51 -> 102 | P51: =C51 -> 1 | Q51: =F51 -> 1 | R51: =E51-1 -> 8 | S51: =IF(D51=D$2,1,IF(D51=D$43,2,IF(D51=D$84,3))) -> 1 | T51: =L51 -> 16.23318 | U51: =IF(H51=H$5,1,2) -> 2 | V51: =MID(A51,11,1) -> 6 | W51: =IF(J51=J$3,1,2) -> 2
A52: Picture_L_6B | B52: 102 | C52: 1 | D52: A | E52: 10 | F52: 3 | G52: 3.37 | H52: C | I52: C | J52: M | K52: M075C.jpg | L52: 13.08296 | M52: 01-30-2012 | N52: =L52-12.95 -> 0.13296 | O52: =B52 -> 102 | P52: =C52 -> 1 | Q52: =F52 -> 3 | R52: =E52-1 -> 9 | S52: =IF(D52=D$2,1,IF(D52=D$43,2,IF(D52=D$84,3))) -> 1 | T52: =L52 -> 13.08296 | U52: =IF(H52=H$5,1,2) -> 1 | V52: =MID(A52,11,1) -> 6 | W52: =IF(J52=J$3,1,2) -> 2
A53: Picture_L_6B | B53: 102 | C53: 1 | D53: A | E53: 11 | F53: 3 | G53: 3.37 | H53: A | I53: L | J53: M | K53: M075L.jpg | L53: 13.34081 | M53: 01-30-2012 | N53: =L53-12.95 -> 0.39081 | O53: =B53 -> 102 | P53: =C53 -> 1 | Q53: =F53 -> 3 | R53: =E53-1 -> 10 | S53: =IF(D53=D$2,1,IF(D53=D$43,2,IF(D53=D$84,3))) -> 1 | T53: =L53 -> 13.34081 | U53: =IF(H53=H$5,1,2) -> 2 | V53: =MID(A53,11,1) -> 6 | W53: =IF(J53=J$3,1,2) -> 2
A54: Picture_L_6B | B54: 102 | C54: 1 | D54: A | E54: 12 | F54: 1 | G54: 5.35 | H54: C | I54: C | J54: M | K54: M055C.jpg | L54: 16.68161 | M54: 01-30-2012 | N54: =L54-12.95 -> 3.73161 | O54: =B54 -> 102 | P54: =C54 -> 1 | Q54: =F54 -> 1 | R54: =E54-1 -> 11 | S54: =IF(D54=D$2,1,IF(D54=D$43,2,IF(D54=D$84,3))) -> 1 | T54: =L54 -> 16.68161 | U54: =IF(H54=H$5,1,2) -> 1 | V54: =MID(A54,11,1) -> 6 | W54: =IF(J54=J$3,1,2) -> 2
A55: Picture_L_6B | B55: 102 | C55: 1 | D55: A | E55: 13 | F55: 2 | G55: 4.75 | H55: A | I55: L | J55: F | K55: F001L.jpg | L55: 14.30493 | M55: 01-30-2012 | N55: =L55-12.95 -> 1.35493 | O55: =B55 -> 102 | P55: =C55 -> 1 | Q55: =F55 -> 2 | R55: =E55-1 -> 12 | S55: =IF(D55=D$2,1,IF(D55=D$43,2,IF(D55=D$84,3))) -> 1 | T55: =L55 -> 14.30493 | U55: =IF(H55=H$5,1,2) -> 2 | V55: =MID(A55,11,1) -> 6 | W55: =IF(J55=J$3,1,2) -> 1
... A83: Picture_L_6B | B83: 102 | C83: 1 | D83: A | E83: 41 | F83: 3 | G83: 2.37 | H83: C | I83: C | J83: F | K83: F110C.jpg | L83: 13.87892 | M83: 01-30-2012 | N83: =L83-12.95 -> 0.92892 | O83: =B83 -> 102 | P83: =C83 -> 1 | Q83: =F83 -> 3 | R83: =E83-1 -> 40 | S83: =IF(D83=D$2,1,IF(D83=D$43,2,IF(D83=D$84,3))) -> 1 | T83: =L83 -> 13.87892 | U83: =IF(H83=H$5,1,2) -> 1 | V83: =MID(A83,11,1) -> 6 | W83: =IF(J83=J$3,1,2) -> 1
A84: Picture_L_6A | B84: 103 | C84: 2 | D84: A | E84: 1 | F84: 0 | H84: 0 | I84: 0 | J84: 0 | K84: F037C.jpg | L84: 18.52018 | M84: 41092 | N84: =L84-12.95 -> 5.57018 | O84: =B84 -> 103 | P84: =C84 -> 2 | Q84: =F84 -> 0 | R84: =E84-1 -> 0 | S84: =IF(D84=D$2,1,IF(D84=D$43,2,IF(D84=D$84,3))) -> 1 | T84: =L84 -> 18.52018 | U84: =IF(H84=H$5,1,2) -> 2 | V84: =MID(A84,11,1) -> 6 | W84: =IF(J84=J$3,1,2) -> 2
...

Sheet overview sessions
C1: correction value | E1: =AVERAGE(E7:E36,E41:E62,E64:E70,E75:E96,E98:E104) -> 5.0577674 | F1: =AVERAGE(F7:F36,F41:F62,F64:F70,F75:F96,F98:F104) -> 5.1211503 | G1: =AVERAGE(G7:G36,G41:G62,G64:G70,G75:G96,G98:G104) -> 6.8267323 | H1: =AVERAGE(H7:H36,H41:H62,H64:H70,H75:H96,H98:H104) -> 5.9289264 | I1: =AVERAGE(I7:I36,I41:I62,I64:I70,I75:I96,I98:I104) -> 3.6945053 | J1: =AVERAGE(J7:J36,J41:J62,J64:J70,J75:J96,J98:J104) -> 5.6546275 | K1: =AVERAGE(K7:K36,K41:K62,K64:K70,K75:K96,K98:K104) -> 4.879786 | L1: =AVERAGE(L7:L36,L41:L62,L64:L70,L75:L96,L98:L104) -> 3.5565398 | N1: =AVERAGE(N7:N36,N41:N62,N64:N70,N75:N96,N98:N104) -> 4.9954289 | O1: =AVERAGE(O7:O36,O41:O62,O64:O70,O75:O96,O98:O104) -> 6.5833602 | P1: =AVERAGE(P7:P36,P41:P62,P64:P70,P75:P96,P98:P104) -> 5.7942682 | Q1: =AVERAGE(Q7:Q36,Q41:Q62,Q64:Q70,Q75:Q96,Q98:Q104) -> 3.6400838 | R1: =AVERAGE(R7:R36,R41:R62,R64:R70,R75:R96,R98:R104) -> 5.5663161 | S1: =AVERAGE(S7:S36,S41:S62,S64:S70,S75:S96,S98:S104) -> 4.712108 | T1: =AVERAGE(T7:T36,T41:T62,T64:T70,T75:T96,T98:T104) -> 3.5098719
A2: =MIN(rawdata!K:K) -> 12.97085 | C2: 12.9
A3: =MAX(rawdata!K:K) -> 25.05605 | F3: Direct gaze | H3: C | N3: Averted gaze | P3: A
C4: Session=1 | G4: 1 | H4: 2 | I4: 3 | J4: 1 | K4: 2 | L4: 3 | O4: 1 | P4: 2 | Q4: 3 | R4: 1 | S4: 2 | T4: 3
E5: VAS | G5: F | J5: M | O5: F | R5: M
E6: all stim | F6: all direct | G6: Attractive | H6: Neutral | I6: Unattractive | J6: Attractive | K6: Neutral | L6: Unattractive | N6: all indirect | O6: Attractive | P6: Neutral | Q6: Unattractive | R6: Attractive | S6: Neutral | T6: Unattractive
A7: A | B7: 1 | C7: A | D7: 101 | E7: =AVERAGEIFS(rawdata!$K:$K,rawdata!$A:$A,'overview sessions'!$D7,rawdata!$B:$B,'overview sessions'!$B$7)-$C$2 -> 5.6117027 | F7: =AVERAGEIFS(rawdata!$K:$K,rawdata!$A:$A,'overview sessions'!$D7,rawdata!$B:$B,'overview sessions'!$B$7,rawdata!$G:$G,'overview sessions'!$H$3)-$C$2 -> 5.5932725 | G7: =AVERAGEIFS(rawdata!$K:$K,rawdata!$A:$A,'overview sessions'!$D7,rawdata!$B:$B,'overview sessions'!$B$7,rawdata!$G:$G,'overview sessions'!$H$3,rawdata!$I:$I,'overview sessions'!$G$5,rawdata!$E:$E,'overview sessions'!G$4)-$C$2 -> 7.23079 | H7: =AVERAGEIFS(rawdata!$K:$K,rawdata!$A:$A,'overview sessions'!$D7,rawdata!$B:$B,'overview sessions'!$B$7,rawdata!$G:$G,'overview sessions'!$H$3,rawdata!$I:$I,'overview sessions'!$G$5,rawdata!$E:$E,'overview sessions'!H$4)-$C$2 -> 6.2171525 | I7: =AVERAGEIFS(rawdata!$K:$K,rawdata!$A:$A,'overview sessions'!$D7,rawdata!$B:$B,'overview sessions'!$B$7,rawdata!$G:$G,'overview sessions'!$H$3,rawdata!$I:$I,'overview sessions'!$G$5,rawdata!$E:$E,'overview sessions'!I$4)-$C$2 -> 2.8324367 | J7: =AVERAGEIFS(rawdata!$K:$K,rawdata!$A:$A,'overview sessions'!$D7,rawdata!$B:$B,'overview sessions'!$B$7,rawdata!$G:$G,'overview sessions'!$H$3,rawdata!$I:$I,'overview sessions'!$J$5,rawdata!$E:$E,'overview sessions'!J$4)-$C$2 -> 7.2457367 | K7: =AVERAGEIFS(rawdata!$K:$K,rawdata!$A:$A,'overview sessions'!$D7,rawdata!$B:$B,'overview sessions'!$B$7,rawdata!$G:$G,'overview sessions'!$H$3,rawdata!$I:$I,'overview sessions'!$J$5,rawdata!$E:$E,'overview sessions'!K$4)-$C$2 -> 6.0517925 | L7: =AVERAGEIFS(rawdata!$K:$K,rawdata!$A:$A,'overview sessions'!$D7,rawdata!$B:$B,'overview sessions'!$B$7,rawdata!$G:$G,'overview sessions'!$H$3,rawdata!$I:$I,'overview sessions'!$J$5,rawdata!$E:$E,'overview sessions'!L$4)-$C$2 -> 3.6209267 | N7: =AVERAGEIFS(rawdata!$K:$K,rawdata!$A:$A,'overview sessions'!$D7,rawdata!$B:$B,'overview sessions'!$B$7,rawdata!$G:$G,'overview sessions'!$P$3)-$C$2 -> 5.538902 | O7: =AVERAGEIFS(rawdata!$K:$K,rawdata!$A:$A,'overview sessions'!$D7,rawdata!$B:$B,'overview sessions'!$B$7,rawdata!$G:$G,'overview sessions'!$P$3,rawdata!$I:$I,'overview sessions'!$G$5,rawdata!$E:$E,'overview sessions'!O$4)-$C$2 -> 7.2868467 | P7: =AVERAGEIFS(rawdata!$K:$K,rawdata!$A:$A,'overview sessions'!$D7,rawdata!$B:$B,'overview sessions'!$B$7,rawdata!$G:$G,'overview sessions'!$P$3,rawdata!$I:$I,'overview sessions'!$G$5,rawdata!$E:$E,'overview sessions'!P$4)-$C$2 -> 6.5198425 | Q7: =AVERAGEIFS(rawdata!$K:$K,rawdata!$A:$A,'overview sessions'!$D7,rawdata!$B:$B,'overview sessions'!$B$7,rawdata!$G:$G,'overview sessions'!$P$3,rawdata!$I:$I,'overview sessions'!$G$5,rawdata!$E:$E,'overview sessions'!Q$4)-$C$2 -> 2.32048 | R7: =AVERAGEIFS(rawdata!$K:$K,rawdata!$A:$A,'overview sessions'!$D7,rawdata!$B:$B,'overview sessions'!$B$7,rawdata!$G:$G,'overview sessions'!$P$3,rawdata!$I:$I,'overview sessions'!$J$5,rawdata!$E:$E,'overview sessions'!R$4)-$C$2 -> 6.9056833 | S7: =AVERAGEIFS(rawdata!$K:$K,rawdata!$A:$A,'overview sessions'!$D7,rawdata!$B:$B,'overview sessions'!$B$7,rawdata!$G:$G,'overview sessions'!$P$3,rawdata!$I:$I,'overview sessions'!$J$5,rawdata!$E:$E,'overview sessions'!S$4)-$C$2 -> 6.4553825 | T7: =AVERAGEIFS(rawdata!$K:$K,rawdata!$A:$A,'overview sessions'!$D7,rawdata!$B:$B,'overview sessions'!$B$7,rawdata!$G:$G,'overview sessions'!$P$3,rawdata!$I:$I,'overview sessions'!$J$5,rawdata!$E:$E,'overview sessions'!T$4)-$C$2 -> 3.1127033
A8: A | B8: 1 | C8: A | D8: 102 | E8: =AVERAGEIFS(rawdata!$K:$K,rawdata!$A:$A,'overview sessions'!$D8,rawdata!$B:$B,'overview sessions'!$B$7)-$C$2 -> 1.5654385 | F8: =AVERAGEIFS(rawdata!$K:$K,rawdata!$A:$A,'overview sessions'!$D8,rawdata!$B:$B,'overview sessions'!$B$7,rawdata!$G:$G,'overview sessions'!$H$3)-$C$2 -> 1.670629 | G8: =AVERAGEIFS(rawdata!$K:$K,rawdata!$A:$A,'overview sessions'!$D8,rawdata!$B:$B,'overview sessions'!$B$7,rawdata!$G:$G,'overview sessions'!$H$3,rawdata!$I:$I,'overview sessions'!$G$5,rawdata!$E:$E,'overview sessions'!G$4)-$C$2 -> 4.0357267 | H8: =AVERAGEIFS(rawdata!$K:$K,rawdata!$A:$A,'overview sessions'!$D8,rawdata!$B:$B,'overview sessions'!$B$7,rawdata!$G:$G,'overview sessions'!$H$3,rawdata!$I:$I,'overview sessions'!$G$5,rawdata!$E:$E,'overview sessions'!H$4)-$C$2 -> 1.9066175 | I8: =AVERAGEIFS(rawdata!$K:$K,rawdata!$A:$A,'overview sessions'!$D8,rawdata!$B:$B,'overview sessions'!$B$7,rawdata!$G:$G,'overview sessions'!$H$3,rawdata!$I:$I,'overview sessions'!$G$5,rawdata!$E:$E,'overview sessions'!I$4)-$C$2 -> 0.47070333 | J8: =AVERAGEIFS(rawdata!$K:$K,rawdata!$A:$A,'overview sessions'!$D8,rawdata!$B:$B,'overview sessions'!$B$7,rawdata!$G:$G,'overview sessions'!$H$3,rawdata!$I:$I,'overview sessions'!$J$5,rawdata!$E:$E,'overview sessions'!J$4)-$C$2 -> 2.6979067 | K8: =AVERAGEIFS(rawdata!$K:$K,rawdata!$A:$A,'overview sessions'!$D8,rawdata!$B:$B,'overview sessions'!$B$7,rawdata!$G:$G,'overview sessions'!$H$3,rawdata!$I:$I,'overview sessions'!$J$5,rawdata!$E:$E,'overview sessions'!K$4)-$C$2 -> 0.9088575 | L8: =AVERAGEIFS(rawdata!$K:$K,rawdata!$A:$A,'overview sessions'!$D8,rawdata!$B:$B,'overview sessions'!$B$7,rawdata!$G:$G,'overview sessions'!$H$3,rawdata!$I:$I,'overview sessions'!$J$5,rawdata!$E:$E,'overview sessions'!L$4)-$C$2 -> 0.17922333 | N8: =AVERAGEIFS(rawdata!$K:$K,rawdata!$A:$A,'overview sessions'!$D8,rawdata!$B:$B,'overview sessions'!$B$7,rawdata!$G:$G,'overview sessions'!$P$3)-$C$2 -> 1.48565 | O8: =AVERAGEIFS(rawdata!$K:$K,rawdata!$A:$A,'overview sessions'!$D8,rawdata!$B:$B,'overview sessions'!$B$7,rawdata!$G:$G,'overview sessions'!$P$3,rawdata!$I:$I,'overview sessions'!$G$5,rawdata!$E:$E,'overview sessions'!O$4)-$C$2 -> 4.0581467 | P8: =AVERAGEIFS(rawdata!$K:$K,rawdata!$A:$A,'overview sessions'!$D8,rawdata!$B:$B,'overview sessions'!$B$7,rawdata!$G:$G,'overview sessions'!$P$3,rawdata!$I:$I,'overview sessions'!$G$5,rawdata!$E:$E,'overview sessions'!P$4)-$C$2 -> 1.34047 | Q8: =AVERAGEIFS(rawdata!$K:$K,rawdata!$A:$A,'overview sessions'!$D8,rawdata!$B:$B,'overview sessions'!$B$7,rawdata!$G:$G,'overview sessions'!$P$3,rawdata!$I:$I,'overview sessions'!$G$5,rawdata!$E:$E,'overview sessions'!Q$4)-$C$2 -> 0.18669667 | R8: =AVERAGEIFS(rawdata!$K:$K,rawdata!$A:$A,'overview sessions'!$D8,rawdata!$B:$B,'overview sessions'!$B$7,rawdata!$G:$G,'overview sessions'!$P$3,rawdata!$I:$I,'overview sessions'!$J$5,rawdata!$E:$E,'overview sessions'!R$4)-$C$2 -> 2.29058 | S8: =AVERAGEIFS(rawdata!$K:$K,rawdata!$A:$A,'overview sessions'!$D8,rawdata!$B:$B,'overview sessions'!$B$7,rawdata!$G:$G,'overview sessions'!$P$3,rawdata!$I:$I,'overview sessions'!$J$5,rawdata!$E:$E,'overview sessions'!S$4)-$C$2 -> 0.886435 | T8: =AVERAGEIFS(rawdata!$K:$K,rawdata!$A:$A,'overview sessions'!$D8,rawdata!$B:$B,'overview sessions'!$B$7,rawdata!$G:$G,'overview sessions'!$P$3,rawdata!$I:$I,'overview sessions'!$J$5,rawdata!$E:$E,'overview sessions'!T$4)-$C$2 -> 0.39970333
A9: C | B9: 1 | C9: C | D9: 103 | E9: =AVERAGEIFS(rawdata!$K:$K,rawdata!$A:$A,'overview sessions'!$D9,rawdata!$B:$B,'overview sessions'!$B$7)-$C$2 -> 3.4879471 | F9: =AVERAGEIFS(rawdata!$K:$K,rawdata!$A:$A,'overview sessions'!$D9,rawdata!$B:$B,'overview sessions'!$B$7,rawdata!$G:$G,'overview sessions'!$H$3)-$C$2 -> 3.4335205 | G9: =AVERAGEIFS(rawdata!$K:$K,rawdata!$A:$A,'overview sessions'!$D9,rawdata!$B:$B,'overview sessions'!$B$7,rawdata!$G:$G,'overview sessions'!$H$3,rawdata!$I:$I,'overview sessions'!$G$5,rawdata!$E:$E,'overview sessions'!G$4)-$C$2 -> 4.4729467 | H9: =AVERAGEIFS(rawdata!$K:$K,rawdata!$A:$A,'overview sessions'!$D9,rawdata!$B:$B,'overview sessions'!$B$7,rawdata!$G:$G,'overview sessions'!$H$3,rawdata!$I:$I,'overview sessions'!$G$5,rawdata!$E:$E,'overview sessions'!H$4)-$C$2 -> 5.6622225 | I9: =AVERAGEIFS(rawdata!$K:$K,rawdata!$A:$A,'overview sessions'!$D9,rawdata!$B:$B,'overview sessions'!$B$7,rawdata!$G:$G,'overview sessions'!$H$3,rawdata!$I:$I,'overview sessions'!$G$5,rawdata!$E:$E,'overview sessions'!I$4)-$C$2 -> 1.5955133 | J9: =AVERAGEIFS(rawdata!$K:$K,rawdata!$A:$A,'overview sessions'!$D9,rawdata!$B:$B,'overview sessions'!$B$7,rawdata!$G:$G,'overview sessions'!$H$3,rawdata!$I:$I,'overview sessions'!$J$5,rawdata!$E:$E,'overview sessions'!J$4)-$C$2 -> 4.2150967 | K9: =AVERAGEIFS(rawdata!$K:$K,rawdata!$A:$A,'overview sessions'!$D9,rawdata!$B:$B,'overview sessions'!$B$7,rawdata!$G:$G,'overview sessions'!$H$3,rawdata!$I:$I,'overview sessions'!$J$5,rawdata!$E:$E,'overview sessions'!K$4)-$C$2 -> 1.6235425 | L9: =AVERAGEIFS(rawdata!$K:$K,rawdata!$A:$A,'overview sessions'!$D9,rawdata!$B:$B,'overview sessions'!$B$7,rawdata!$G:$G,'overview sessions'!$H$3,rawdata!$I:$I,'overview sessions'!$J$5,rawdata!$E:$E,'overview sessions'!L$4)-$C$2 -> 2.8922267 | N9: =AVERAGEIFS(rawdata!$K:$K,rawdata!$A:$A,'overview sessions'!$D9,rawdata!$B:$B,'overview sessions'!$B$7,rawdata!$G:$G,'overview sessions'!$P$3)-$C$2 -> 3.5299325 | O9: =AVERAGEIFS(rawdata!$K:$K,rawdata!$A:$A,'overview sessions'!$D9,rawdata!$B:$B,'overview sessions'!$B$7,rawdata!$G:$G,'overview sessions'!$P$3,rawdata!$I:$I,'overview sessions'!$G$5,rawdata!$E:$E,'overview sessions'!O$4)-$C$2 -> 6.74873 | P9: =AVERAGEIFS(rawdata!$K:$K,rawdata!$A:$A,'overview sessions'!$D9,rawdata!$B:$B,'overview sessions'!$B$7,rawdata!$G:$G,'overview sessions'!$P$3,rawdata!$I:$I,'overview sessions'!$G$5,rawdata!$E:$E,'overview sessions'!P$4)-$C$2 -> 5.774325 | Q9: =AVERAGEIFS(rawdata!$K:$K,rawdata!$A:$A,'overview sessions'!$D9,rawdata!$B:$B,'overview sessions'!$B$7,rawdata!$G:$G,'overview sessions'!$P$3,rawdata!$I:$I,'overview sessions'!$G$5,rawdata!$E:$E,'overview sessions'!Q$4)-$C$2 -> 2.66054 | R9: =AVERAGEIFS(rawdata!$K:$K,rawdata!$A:$A,'overview sessions'!$D9,rawdata!$B:$B,'overview sessions'!$B$7,rawdata!$G:$G,'overview sessions'!$P$3,rawdata!$I:$I,'overview sessions'!$J$5,rawdata!$E:$E,'overview sessions'!R$4)-$C$2 -> 2.7988033 | S9: =AVERAGEIFS(rawdata!$K:$K,rawdata!$A:$A,'overview sessions'!$D9,rawdata!$B:$B,'overview sessions'!$B$7,rawdata!$G:$G,'overview sessions'!$P$3,rawdata!$I:$I,'overview sessions'!$J$5,rawdata!$E:$E,'overview sessions'!S$4)-$C$2 -> 1.7384525 | T9: =AVERAGEIFS(rawdata!$K:$K,rawdata!$A:$A,'overview sessions'!$D9,rawdata!$B:$B,'overview sessions'!$B$7,rawdata!$G:$G,'overview sessions'!$P$3,rawdata!$I:$I,'overview sessions'!$J$5,rawdata!$E:$E,'overview sessions'!T$4)-$C$2 -> 1.3077733
A10: C | B10: 1 | C10: C | D10: 104 | E10: =AVERAGEIFS(rawdata!$K:$K,rawdata!$A:$A,'overview sessions'!$D10,rawdata!$B:$B,'overview sessions'!$B$7)-$C$2 -> 5.6475234 | F10: =AVERAGEIFS(rawdata!$K:$K,rawdata!$A:$A,'overview sessions'!$D10,rawdata!$B:$B,'overview sessions'!$B$7,rawdata!$G:$G,'overview sessions'!$H$3)-$C$2 -> 6.773767 | G10: =AVERAGEIFS(rawdata!$K:$K,rawdata!$A:$A,'overview sessions'!$D10,rawdata!$B:$B,'overview sessions'!$B$7,rawdata!$G:$G,'overview sessions'!$H$3,rawdata!$I:$I,'overview sessions'!$G$5,rawdata!$E:$E,'overview sessions'!G$4)-$C$2 -> 7.4213767 | H10: =AVERAGEIFS(rawdata!$K:$K,rawdata!$A:$A,'overview sessions'!$D10,rawdata!$B:$B,'overview sessions'!$B$7,rawdata!$G:$G,'overview sessions'!$H$3,rawdata!$I:$I,'overview sessions'!$G$5,rawdata!$E:$E,'overview sessions'!H$4)-$C$2 -> 6.8813925 | I10: =AVERAGEIFS(rawdata!$K:$K,rawdata!$A:$A,'overview sessions'!$D10,rawdata!$B:$B,'overview sessions'!$B$7,rawdata!$G:$G,'overview sessions'!$H$3,rawdata!$I:$I,'overview sessions'!$G$5,rawdata!$E:$E,'overview sessions'!I$4)-$C$2 -> 6.7562033 | J10: =AVERAGEIFS(rawdata!$K:$K,rawdata!$A:$A,'overview sessions'!$D10,rawdata!$B:$B,'overview sessions'!$B$7,rawdata!$G:$G,'overview sessions'!$H$3,rawdata!$I:$I,'overview sessions'!$J$5,rawdata!$E:$E,'overview sessions'!J$4)-$C$2 -> 8.0005967 | K10: =AVERAGEIFS(rawdata!$K:$K,rawdata!$A:$A,'overview sessions'!$D10,rawdata!$B:$B,'overview sessions'!$B$7,rawdata!$G:$G,'overview sessions'!$H$3,rawdata!$I:$I,'overview sessions'!$J$5,rawdata!$E:$E,'overview sessions'!K$4)-$C$2 -> 6.929035 | L10: =AVERAGEIFS(rawdata!$K:$K,rawdata!$A:$A,'overview sessions'!$D10,rawdata!$B:$B,'overview sessions'!$B$7,rawdata!$G:$G,'overview sessions'!$H$3,rawdata!$I:$I,'overview sessions'!$J$5,rawdata!$E:$E,'overview sessions'!L$4)-$C$2 -> 4.5663667 | N10: =AVERAGEIFS(rawdata!$K:$K,rawdata!$A:$A,'overview sessions'!$D10,rawdata!$B:$B,'overview sessions'!$B$7,rawdata!$G:$G,'overview sessions'!$P$3)-$C$2 -> 4.4598665 | O10: =AVERAGEIFS(rawdata!$K:$K,rawdata!$A:$A,'overview sessions'!$D10,rawdata!$B:$B,'overview sessions'!$B$7,rawdata!$G:$G,'overview sessions'!$P$3,rawdata!$I:$I,'overview sessions'!$G$5,rawdata!$E:$E,'overview sessions'!O$4)-$C$2 -> 5.42586 | P10: =AVERAGEIFS(rawdata!$K:$K,rawdata!$A:$A,'overview sessions'!$D10,rawdata!$B:$B,'overview sessions'!$B$7,rawdata!$G:$G,'overview sessions'!$P$3,rawdata!$I:$I,'overview sessions'!$G$5,rawdata!$E:$E,'overview sessions'!P$4)-$C$2 -> 5.25583 | Q10: =AVERAGEIFS(rawdata!$K:$K,rawdata!$A:$A,'overview sessions'!$D10,rawdata!$B:$B,'overview sessions'!$B$7,rawdata!$G:$G,'overview sessions'!$P$3,rawdata!$I:$I,'overview sessions'!$G$5,rawdata!$E:$E,'overview sessions'!Q$4)-$C$2 -> 3.1874433 | R10: =AVERAGEIFS(rawdata!$K:$K,rawdata!$A:$A,'overview sessions'!$D10,rawdata!$B:$B,'overview sessions'!$B$7,rawdata!$G:$G,'overview sessions'!$P$3,rawdata!$I:$I,'overview sessions'!$J$5,rawdata!$E:$E,'overview sessions'!R$4)-$C$2 -> 5.81076 | S10: =AVERAGEIFS(rawdata!$K:$K,rawdata!$A:$A,'overview sessions'!$D10,rawdata!$B:$B,'overview sessions'!$B$7,rawdata!$G:$G,'overview sessions'!$P$3,rawdata!$I:$I,'overview sessions'!$J$5,rawdata!$E:$E,'overview sessions'!S$4)-$C$2 -> 4.070295 | T10: =AVERAGEIFS(rawdata!$K:$K,rawdata!$A:$A,'overview sessions'!$D10,rawdata!$B:$B,'overview sessions'!$B$7,rawdata!$G:$G,'overview sessions'!$P$3,rawdata!$I:$I,'overview sessions'!$J$5,rawdata!$E:$E,'overview sessions'!T$4)-$C$2 -> 2.8735467
A11: B | B11: 1 | C11: B | D11: 105 | E11: =AVERAGEIFS(rawdata!$K:$K,rawdata!$A:$A,'overview sessions'!$D11,rawdata!$B:$B,'overview sessions'!$B$7)-$C$2 -> 4.8447222 | F11: =AVERAGEIFS(rawdata!$K:$K,rawdata!$A:$A,'overview sessions'!$D11,rawdata!$B:$B,'overview sessions'!$B$7,rawdata!$G:$G,'overview sessions'!$H$3)-$C$2 -> 5.3174885 | G11: =AVERAGEIFS(rawdata!$K:$K,rawdata!$A:$A,'overview sessions'!$D11,rawdata!$B:$B,'overview sessions'!$B$7,rawdata!$G:$G,'overview sessions'!$H$3,rawdata!$I:$I,'overview sessions'!$G$5,rawdata!$E:$E,'overview sessions'!G$4)-$C$2 -> 6.5618833 | H11: =AVERAGEIFS(rawdata!$K:$K,rawdata!$A:$A,'overview sessions'!$D11,rawdata!$B:$B,'overview sessions'!$B$7,rawdata!$G:$G,'overview sessions'!$H$3,rawdata!$I:$I,'overview sessions'!$G$5,rawdata!$E:$E,'overview sessions'!H$4)-$C$2 -> 5.5781375 | I11: =AVERAGEIFS(rawdata!$K:$K,rawdata!$A:$A,'overview sessions'!$D11,rawdata!$B:$B,'overview sessions'!$B$7,rawdata!$G:$G,'overview sessions'!$H$3,rawdata!$I:$I,'overview sessions'!$G$5,rawdata!$E:$E,'overview sessions'!I$4)-$C$2 -> 3.5387133 | J11: =AVERAGEIFS(rawdata!$K:$K,rawdata!$A:$A,'overview sessions'!$D11,rawdata!$B:$B,'overview sessions'!$B$7,rawdata!$G:$G,'overview sessions'!$H$3,rawdata!$I:$I,'overview sessions'!$J$5,rawdata!$E:$E,'overview sessions'!J$4)-$C$2 -> 6.1358767 | K11: =AVERAGEIFS(rawdata!$K:$K,rawdata!$A:$A,'overview sessions'!$D11,rawdata!$B:$B,'overview sessions'!$B$7,rawdata!$G:$G,'overview sessions'!$H$3,rawdata!$I:$I,'overview sessions'!$J$5,rawdata!$E:$E,'overview sessions'!K$4)-$C$2 -> 5.14372 | L11: =AVERAGEIFS(rawdata!$K:$K,rawdata!$A:$A,'overview sessions'!$D11,rawdata!$B:$B,'overview sessions'!$B$7,rawdata!$G:$G,'overview sessions'!$H$3,rawdata!$I:$I,'overview sessions'!$J$5,rawdata!$E:$E,'overview sessions'!L$4)-$C$2 -> 4.91764 | N11: =AVERAGEIFS(rawdata!$K:$K,rawdata!$A:$A,'overview sessions'!$D11,rawdata!$B:$B,'overview sessions'!$B$7,rawdata!$G:$G,'overview sessions'!$P$3)-$C$2 -> 4.4161425 | O11: =AVERAGEIFS(rawdata!$K:$K,rawdata!$A:$A,'overview sessions'!$D11,rawdata!$B:$B,'overview sessions'!$B$7,rawdata!$G:$G,'overview sessions'!$P$3,rawdata!$I:$I,'overview sessions'!$G$5,rawdata!$E:$E,'overview sessions'!O$4)-$C$2 -> 5.3585933 | P11: =AVERAGEIFS(rawdata!$K:$K,rawdata!$A:$A,'overview sessions'!$D11,rawdata!$B:$B,'overview sessions'!$B$7,rawdata!$G:$G,'overview sessions'!$P$3,rawdata!$I:$I,'overview sessions'!$G$5,rawdata!$E:$E,'overview sessions'!P$4)-$C$2 -> 4.67287 | Q11: =AVERAGEIFS(rawdata!$K:$K,rawdata!$A:$A,'overview sessions'!$D11,rawdata!$B:$B,'overview sessions'!$B$7,rawdata!$G:$G,'overview sessions'!$P$3,rawdata!$I:$I,'overview sessions'!$G$5,rawdata!$E:$E,'overview sessions'!Q$4)-$C$2 -> 3.6433467 | R11: =AVERAGEIFS(rawdata!$K:$K,rawdata!$A:$A,'overview sessions'!$D11,rawdata!$B:$B,'overview sessions'!$B$7,rawdata!$G:$G,'overview sessions'!$P$3,rawdata!$I:$I,'overview sessions'!$J$5,rawdata!$E:$E,'overview sessions'!R$4)-$C$2 -> 5.5641233 | S11: =AVERAGEIFS(rawdata!$K:$K,rawdata!$A:$A,'overview sessions'!$D11,rawdata!$B:$B,'overview sessions'!$B$7,rawdata!$G:$G,'overview sessions'!$P$3,rawdata!$I:$I,'overview sessions'!$J$5,rawdata!$E:$E,'overview sessions'!S$4)-$C$2 -> 4.1880025 | T11: =AVERAGEIFS(rawdata!$K:$K,rawdata!$A:$A,'overview sessions'!$D11,rawdata!$B:$B,'overview sessions'!$B$7,rawdata!$G:$G,'overview sessions'!$P$3,rawdata!$I:$I,'overview sessions'!$J$5,rawdata!$E:$E,'overview sessions'!T$4)-$C$2 -> 3.06039
A12: B | B12: 1 | C12: B | D12: 106 | E12: =AVERAGEIFS(rawdata!$K:$K,rawdata!$A:$A,'overview sessions'!$D12,rawdata!$B:$B,'overview sessions'!$B$7)-$C$2 -> 5.7011156 | F12: =AVERAGEIFS(rawdata!$K:$K,rawdata!$A:$A,'overview sessions'!$D12,rawdata!$B:$B,'overview sessions'!$B$7,rawdata!$G:$G,'overview sessions'!$H$3)-$C$2 -> 6.2227575 | G12: =AVERAGEIFS(rawdata!$K:$K,rawdata!$A:$A,'overview sessions'!$D12,rawdata!$B:$B,'overview sessions'!$B$7,rawdata!$G:$G,'overview sessions'!$H$3,rawdata!$I:$I,'overview sessions'!$G$5,rawdata!$E:$E,'overview sessions'!G$4)-$C$2 -> 8.3929733 | H12: =AVERAGEIFS(rawdata!$K:$K,rawdata!$A:$A,'overview sessions'!$D12,rawdata!$B:$B,'overview sessions'!$B$7,rawdata!$G:$G,'overview sessions'!$H$3,rawdata!$I:$I,'overview sessions'!$G$5,rawdata!$E:$E,'overview sessions'!H$4)-$C$2 -> 7.5344175 | I12: =AVERAGEIFS(rawdata!$K:$K,rawdata!$A:$A,'overview sessions'!$D12,rawdata!$B:$B,'overview sessions'!$B$7,rawdata!$G:$G,'overview sessions'!$H$3,rawdata!$I:$I,'overview sessions'!$G$5,rawdata!$E:$E,'overview sessions'!I$4)-$C$2 -> 2.70538 | J12: =AVERAGEIFS(rawdata!$K:$K,rawdata!$A:$A,'overview sessions'!$D12,rawdata!$B:$B,'overview sessions'!$B$7,rawdata!$G:$G,'overview sessions'!$H$3,rawdata!$I:$I,'overview sessions'!$J$5,rawdata!$E:$E,'overview sessions'!J$4)-$C$2 -> 6.9318367 | K12: =AVERAGEIFS(rawdata!$K:$K,rawdata!$A:$A,'overview sessions'!$D12,rawdata!$B:$B,'overview sessions'!$B$7,rawdata!$G:$G,'overview sessions'!$H$3,rawdata!$I:$I,'overview sessions'!$J$5,rawdata!$E:$E,'overview sessions'!K$4)-$C$2 -> 7.029935 | L12: =AVERAGEIFS(rawdata!$K:$K,rawdata!$A:$A,'overview sessions'!$D12,rawdata!$B:$B,'overview sessions'!$B$7,rawdata!$G:$G,'overview sessions'!$H$3,rawdata!$I:$I,'overview sessions'!$J$5,rawdata!$E:$E,'overview sessions'!L$4)-$C$2 -> 4.0357233 | N12: =AVERAGEIFS(rawdata!$K:$K,rawdata!$A:$A,'overview sessions'!$D12,rawdata!$B:$B,'overview sessions'!$B$7,rawdata!$G:$G,'overview sessions'!$P$3)-$C$2 -> 5.310202 | O12: =AVERAGEIFS(rawdata!$K:$K,rawdata!$A:$A,'overview sessions'!$D12,rawdata!$B:$B,'overview sessions'!$B$7,rawdata!$G:$G,'overview sessions'!$P$3,rawdata!$I:$I,'overview sessions'!$G$5,rawdata!$E:$E,'overview sessions'!O$4)-$C$2 -> 7.4325867 | P12: =AVERAGEIFS(rawdata!$K:$K,rawdata!$A:$A,'overview sessions'!$D12,rawdata!$B:$B,'overview sessions'!$B$7,rawdata!$G:$G,'overview sessions'!$P$3,rawdata!$I:$I,'overview sessions'!$G$5,rawdata!$E:$E,'overview sessions'!P$4)-$C$2 -> 6.760875 | Q12: =AVERAGEIFS(rawdata!$K:$K,rawdata!$A:$A,'overview sessions'!$D12,rawdata!$B:$B,'overview sessions'!$B$7,rawdata!$G:$G,'overview sessions'!$P$3,rawdata!$I:$I,'overview sessions'!$G$5,rawdata!$E:$E,'overview sessions'!Q$4)-$C$2 -> 3.6844533 | R12: =AVERAGEIFS(rawdata!$K:$K,rawdata!$A:$A,'overview sessions'!$D12,rawdata!$B:$B,'overview sessions'!$B$7,rawdata!$G:$G,'overview sessions'!$P$3,rawdata!$I:$I,'overview sessions'!$J$5,rawdata!$E:$E,'overview sessions'!R$4)-$C$2 -> 6.4310933 | S12: =AVERAGEIFS(rawdata!$K:$K,rawdata!$A:$A,'overview sessions'!$D12,rawdata!$B:$B,'overview sessions'!$B$7,rawdata!$G:$G,'overview sessions'!$P$3,rawdata!$I:$I,'overview sessions'!$J$5,rawdata!$E:$E,'overview sessions'!S$4)-$C$2 -> 4.1459625 | T12: =AVERAGEIFS(rawdata!$K:$K,rawdata!$A:$A,'overview sessions'!$D12,rawdata!$B:$B,'overview sessions'!$B$7,rawdata!$G:$G,'overview sessions'!$P$3,rawdata!$I:$I,'overview sessions'!$J$5,rawdata!$E:$E,'overview sessions'!T$4)-$C$2 -> 3.3107633
A13: A | B13: 1 | C13: A | D13: 107 | E13: =AVERAGEIFS(rawdata!$K:$K,rawdata!$A:$A,'overview sessions'!$D13,rawdata!$B:$B,'overview sessions'!$B$7)-$C$2 -> 3.922159 | F13: =AVERAGEIFS(rawdata!$K:$K,rawdata!$A:$A,'overview sessions'!$D13,rawdata!$B:$B,'overview sessions'!$B$7,rawdata!$G:$G,'overview sessions'!$H$3)-$C$2 -> 3.8180495 | G13: =AVERAGEIFS(rawdata!$K:$K,rawdata!$A:$A,'overview sessions'!$D13,rawdata!$B:$B,'overview sessions'!$B$7,rawdata!$G:$G,'overview sessions'!$H$3,rawdata!$I:$I,'overview sessions'!$G$5,rawdata!$E:$E,'overview sessions'!G$4)-$C$2 -> 4.2562033 | H13: =AVERAGEIFS(rawdata!$K:$K,rawdata!$A:$A,'overview sessions'!$D13,rawdata!$B:$B,'overview sessions'!$B$7,rawdata!$G:$G,'overview sessions'!$H$3,rawdata!$I:$I,'overview sessions'!$G$5,rawdata!$E:$E,'overview sessions'!H$4)-$C$2 -> 5.2698425 | I13: =AVERAGEIFS(rawdata!$K:$K,rawdata!$A:$A,'overview sessions'!$D13,rawdata!$B:$B,'overview sessions'!$B$7,rawdata!$G:$G,'overview sessions'!$H$3,rawdata!$I:$I,'overview sessions'!$G$5,rawdata!$E:$E,'overview sessions'!I$4)-$C$2 -> 2.2868467 | J13: =AVERAGEIFS(rawdata!$K:$K,rawdata!$A:$A,'overview sessions'!$D13,rawdata!$B:$B,'overview sessions'!$B$7,rawdata!$G:$G,'overview sessions'!$H$3,rawdata!$I:$I,'overview sessions'!$J$5,rawdata!$E:$E,'overview sessions'!J$4)-$C$2 -> 3.63214 | K13: =AVERAGEIFS(rawdata!$K:$K,rawdata!$A:$A,'overview sessions'!$D13,rawdata!$B:$B,'overview sessions'!$B$7,rawdata!$G:$G,'overview sessions'!$H$3,rawdata!$I:$I,'overview sessions'!$J$5,rawdata!$E:$E,'overview sessions'!K$4)-$C$2 -> 3.51816 | L13: =AVERAGEIFS(rawdata!$K:$K,rawdata!$A:$A,'overview sessions'!$D13,rawdata!$B:$B,'overview sessions'!$B$7,rawdata!$G:$G,'overview sessions'!$H$3,rawdata!$I:$I,'overview sessions'!$J$5,rawdata!$E:$E,'overview sessions'!L$4)-$C$2 -> 3.5611367 | N13: =AVERAGEIFS(rawdata!$K:$K,rawdata!$A:$A,'overview sessions'!$D13,rawdata!$B:$B,'overview sessions'!$B$7,rawdata!$G:$G,'overview sessions'!$P$3)-$C$2 -> 4.0204035 | O13: =AVERAGEIFS(rawdata!$K:$K,rawdata!$A:$A,'overview sessions'!$D13,rawdata!$B:$B,'overview sessions'!$B$7,rawdata!$G:$G,'overview sessions'!$P$3,rawdata!$I:$I,'overview sessions'!$G$5,rawdata!$E:$E,'overview sessions'!O$4)-$C$2 -> 5.0222733 | P13: =AVERAGEIFS(rawdata!$K:$K,rawdata!$A:$A,'overview sessions'!$D13,rawdata!$B:$B,'overview sessions'!$B$7,rawdata!$G:$G,'overview sessions'!$P$3,rawdata!$I:$I,'overview sessions'!$G$5,rawdata!$E:$E,'overview sessions'!P$4)-$C$2 -> 5.2950675 | Q13: =AVERAGEIFS(rawdata!$K:$K,rawdata!$A:$A,'overview sessions'!$D13,rawdata!$B:$B,'overview sessions'!$B$7,rawdata!$G:$G,'overview sessions'!$P$3,rawdata!$I:$I,'overview sessions'!$G$5,rawdata!$E:$E,'overview sessions'!Q$4)-$C$2 -> 2.5857967 | R13: =AVERAGEIFS(rawdata!$K:$K,rawdata!$A:$A,'overview sessions'!$D13,rawdata!$B:$B,'overview sessions'!$B$7,rawdata!$G:$G,'overview sessions'!$P$3,rawdata!$I:$I,'overview sessions'!$J$5,rawdata!$E:$E,'overview sessions'!R$4)-$C$2 -> 3.88251 | S13: =AVERAGEIFS(rawdata!$K:$K,rawdata!$A:$A,'overview sessions'!$D13,rawdata!$B:$B,'overview sessions'!$B$7,rawdata!$G:$G,'overview sessions'!$P$3,rawdata!$I:$I,'overview sessions'!$J$5,rawdata!$E:$E,'overview sessions'!S$4)-$C$2 -> 3.520965 | T13: =AVERAGEIFS(rawdata!$K:$K,rawdata!$A:$A,'overview sessions'!$D13,rawdata!$B:$B,'overview sessions'!$B$7,rawdata!$G:$G,'overview sessions'!$P$3,rawdata!$I:$I,'overview sessions'!$J$5,rawdata!$E:$E,'overview sessions'!T$4)-$C$2 -> 3.5574
